在 Python 中，所有异常必须为一个派生自 [`BaseException`](https://www.bookstack.cn/read/python-3.10.0-zh/177bd954d1cc6696.md#BaseException) 的类的实例。 在带有提及一个特定类的 [`except`](https://www.bookstack.cn/read/python-3.10.0-zh/e64650a44ed4d418.md#except) 子句的 [`try`](https://www.bookstack.cn/read/python-3.10.0-zh/e64650a44ed4d418.md#try) 语句中，该子句也会处理任何派生自该类的异常类（但不处理 *它* 所派生出的异常类）。 通过子类化创建的两个不相关异常类永远是不等效的，既使它们具有相同的名称。

下面列出的内置异常可通过解释器或内置函数来生成。除非另有说明，它们都会具有一个提示导致错误详细原因的“关联值”。 这可以是一个字符串或由多个信息项（例如一个错误码和一个解释错误的字符串）组成的元组。 关联值通常会作为参数被传递给异常类的构造器。

用户代码可以引发内置异常。 这可被用于测试异常处理程序或报告错误条件，“就像” 在解释器引发了相同异常的情况时一样；但是请注意，没有任何机制能防止用户代码引发不适当的错误。

内置异常类可以被子类化以定义新的异常；鼓励程序员从 [`Exception`](https://www.bookstack.cn/read/python-3.10.0-zh/177bd954d1cc6696.md#Exception) 类或它的某个子类而不是从 [`BaseException`](https://www.bookstack.cn/read/python-3.10.0-zh/177bd954d1cc6696.md#BaseException) 来派生新的异常。 关于定义异常的更多信息可以在 Python 教程的 [用户自定义异常](https://www.bookstack.cn/read/python-3.10.0-zh/cabaa8382e33a630.md#tut-userexceptions) 部分查看。

当在 [`except`](https://www.bookstack.cn/read/python-3.10.0-zh/e64650a44ed4d418.md#except) 或 [`finally`](https://www.bookstack.cn/read/python-3.10.0-zh/e64650a44ed4d418.md#finally) 子句中引发（或重新引发）异常时，`__context__` 会被自动设为所捕获的最后一个异常；如果新的异常未被处理，则最终显示的回溯信息将包括原始的异常和最后的异常。

当引发一个新的异常（而不是简单地使用 `raise` 来重新引发 当前在处理的异常）时，隐式的异常上下文可以通过使用带有 [`raise`](https://www.bookstack.cn/read/python-3.10.0-zh/c8810d126a4a3f87.md#raise) 的 [`from`](https://www.bookstack.cn/read/python-3.10.0-zh/c8810d126a4a3f87.md#raise) 子句来补充一个显式的原因:

~~~python
raise new_exc from original_exc
~~~

跟在 [`from`](https://www.bookstack.cn/read/python-3.10.0-zh/c8810d126a4a3f87.md#raise) 之后一表达式必须为一个异常或 `None`。 它将在所引发的异常上被设置为 `__cause__`。 设置 `__cause__` 还会隐式地将 `__suppress_context__` 属性设为 `True`，这样使用 `raise new_exc from None` 可以有效地将旧异常替换为新异常来显示其目的 (例如将 [`KeyError`](https://www.bookstack.cn/read/python-3.10.0-zh/177bd954d1cc6696.md#KeyError) 转换为 [`AttributeError`](https://www.bookstack.cn/read/python-3.10.0-zh/177bd954d1cc6696.md#AttributeError))，同时让旧异常在 `__context__` 中保持可用状态以便在调试时进行内省。

除了异常本身的回溯以外，默认的回溯还会显示这些串连的异常。 `__cause__` 中的显式串连异常如果存在将总是显示。 `__context__` 中的隐式串连异常仅在 `__cause__` 为 [`None`](https://www.bookstack.cn/read/python-3.10.0-zh/a385553acf159919.md#None) 并且 `__suppress_context__` 为假值时显示。

不论在哪种情况下，异常本身总会在任何串连异常之后显示，以便回溯的最后一行总是显示所引发的最后一个异常。

# 基类

下列异常主要被用作其他异常的基类。

*exception* `BaseException`

所有内置异常的基类。 它不应该被用户自定义类直接继承 (这种情况请使用 [`Exception`](https://www.bookstack.cn/read/python-3.10.0-zh/177bd954d1cc6696.md#Exception))。 如果在此类的实例上调用 [`str()`](https://www.bookstack.cn/read/python-3.10.0-zh/7adaf5f79c9e977a.md#str)，则会返回实例的参数表示，或者当没有参数时返回空字符串。

- `args`

  传给异常构造器的参数元组。 某些内置异常 (例如 [`OSError`](https://www.bookstack.cn/read/python-3.10.0-zh/177bd954d1cc6696.md#OSError)) 接受特定数量的参数并赋予此元组中的元素特殊的含义，而其他异常通常只接受一个给出错误信息的单独字符串。

- `with_traceback`(*tb*)

  此方法会将 *tb* 设为新的异常回溯信息并返回异常对象。 它在 [**PEP 3134**](https://www.python.org/dev/peps/pep-3134) 的异常链特性可用之前更为常用。 下面的例子演示了我们如何将一个 `SomeException` 实例转换为 `OtherException` 实例而保留回溯信息。 异常一旦被引发，当前帧会被推至 `OtherException` 的回溯栈顶端，就像当我们允许原始 `SomeException` 被传播给调用方时它的回溯栈将会发生的情形一样。

*exception* `Exception`

所有内置的非系统退出类异常都派生自此类。 所有用户自定义异常也应当派生自此类。

*exception* `ArithmeticError`

此基类用于派生针对各种算术类错误而引发的内置异常: [`OverflowError`](https://www.bookstack.cn/read/python-3.10.0-zh/177bd954d1cc6696.md#OverflowError), [`ZeroDivisionError`](https://www.bookstack.cn/read/python-3.10.0-zh/177bd954d1cc6696.md#ZeroDivisionError), [`FloatingPointError`](https://www.bookstack.cn/read/python-3.10.0-zh/177bd954d1cc6696.md#FloatingPointError)。

*exception* `BufferError`

当与 [缓冲区](https://www.bookstack.cn/read/python-3.10.0-zh/bb3925174f309147.md#bufferobjects) 相关的操作无法执行时将被引发。

*exception* `LookupError`

此基类用于派生当映射或序列所使用的键或索引无效时引发的异常: [`IndexError`](https://www.bookstack.cn/read/python-3.10.0-zh/177bd954d1cc6696.md#IndexError), [`KeyError`](https://www.bookstack.cn/read/python-3.10.0-zh/177bd954d1cc6696.md#KeyError)。 这可以通过 [`codecs.lookup()`](https://www.bookstack.cn/read/python-3.10.0-zh/293ee43d4addffee.md#codecs.lookup) 来直接

